2025-07-29 00:12:55,287 INFO    MainThread:34751 [wandb_setup.py:_flush():67] Current SDK version is 0.19.9
2025-07-29 00:12:55,288 INFO    MainThread:34751 [wandb_setup.py:_flush():67] Configure stats pid to 34751
2025-07-29 00:12:55,288 INFO    MainThread:34751 [wandb_setup.py:_flush():67] Loading settings from /Users/luosmallrui/.config/wandb/settings
2025-07-29 00:12:55,288 INFO    MainThread:34751 [wandb_setup.py:_flush():67] Loading settings from /Users/luosmallrui/Downloads/DTN/wandb/settings
2025-07-29 00:12:55,288 INFO    MainThread:34751 [wandb_setup.py:_flush():67] Loading settings from environment variables
2025-07-29 00:12:55,288 INFO    MainThread:34751 [wandb_init.py:setup_run_log_directory():662] Logging user logs to /Users/luosmallrui/Downloads/DTN/wandb/run-20250729_001255-m2geavlj/logs/debug.log
2025-07-29 00:12:55,288 INFO    MainThread:34751 [wandb_init.py:setup_run_log_directory():663] Logging internal logs to /Users/luosmallrui/Downloads/DTN/wandb/run-20250729_001255-m2geavlj/logs/debug-internal.log
2025-07-29 00:12:55,288 INFO    MainThread:34751 [wandb_init.py:init():781] calling init triggers
2025-07-29 00:12:55,288 INFO    MainThread:34751 [wandb_init.py:init():786] wandb.init called with sweep_config: {}
config: {'_wandb': {}}
2025-07-29 00:12:55,288 INFO    MainThread:34751 [wandb_init.py:init():809] starting backend
2025-07-29 00:12:55,288 INFO    MainThread:34751 [wandb_init.py:init():813] sending inform_init request
2025-07-29 00:12:55,318 INFO    MainThread:34751 [backend.py:_multiprocessing_setup():101] multiprocessing start_methods=spawn,fork,forkserver, using: spawn
2025-07-29 00:12:55,318 INFO    MainThread:34751 [wandb_init.py:init():823] backend started and connected
2025-07-29 00:12:55,322 INFO    MainThread:34751 [wandb_init.py:init():915] updated telemetry
2025-07-29 00:12:55,334 INFO    MainThread:34751 [wandb_init.py:init():939] communicating run to backend with 90.0 second timeout
2025-07-29 00:13:10,264 INFO    Thread-4  :34751 [retry.py:__call__():175] [no run ID] Retry attempt failed:
Traceback (most recent call last):
  File "/Users/luosmallrui/Library/Python/3.9/lib/python/site-packages/urllib3/connectionpool.py", line 713, in urlopen
    self._prepare_proxy(conn)
  File "/Users/luosmallrui/Library/Python/3.9/lib/python/site-packages/urllib3/connectionpool.py", line 1015, in _prepare_proxy
    conn.connect()
  File "/Users/luosmallrui/Library/Python/3.9/lib/python/site-packages/urllib3/connection.py", line 419, in connect
    self.sock = ssl_wrap_socket(
  File "/Users/luosmallrui/Library/Python/3.9/lib/python/site-packages/urllib3/util/ssl_.py", line 458, in ssl_wrap_socket
    ssl_sock = _ssl_wrap_socket_impl(
  File "/Users/luosmallrui/Library/Python/3.9/lib/python/site-packages/urllib3/util/ssl_.py", line 502, in _ssl_wrap_socket_impl
    return ssl_context.wrap_socket(sock, server_hostname=server_hostname)
  File "/Library/Developer/CommandLineTools/Library/Frameworks/Python3.framework/Versions/3.9/lib/python3.9/ssl.py", line 500, in wrap_socket
    return self.sslsocket_class._create(
  File "/Library/Developer/CommandLineTools/Library/Frameworks/Python3.framework/Versions/3.9/lib/python3.9/ssl.py", line 1040, in _create
    self.do_handshake()
  File "/Library/Developer/CommandLineTools/Library/Frameworks/Python3.framework/Versions/3.9/lib/python3.9/ssl.py", line 1309, in do_handshake
    self._sslobj.do_handshake()
socket.timeout: _ssl.c:1112: The handshake operation timed out

During handling of the above exception, another exception occurred:

Traceback (most recent call last):
  File "/Users/luosmallrui/Library/Python/3.9/lib/python/site-packages/requests/adapters.py", line 667, in send
    resp = conn.urlopen(
  File "/Users/luosmallrui/Library/Python/3.9/lib/python/site-packages/urllib3/connectionpool.py", line 802, in urlopen
    retries = retries.increment(
  File "/Users/luosmallrui/Library/Python/3.9/lib/python/site-packages/urllib3/util/retry.py", line 594, in increment
    raise MaxRetryError(_pool, url, error or ResponseError(cause))
urllib3.exceptions.MaxRetryError: HTTPSConnectionPool(host='api.wandb.ai', port=443): Max retries exceeded with url: /graphql (Caused by ProxyError('Cannot connect to proxy.', timeout('_ssl.c:1112: The handshake operation timed out')))

During handling of the above exception, another exception occurred:

Traceback (most recent call last):
  File "/Users/luosmallrui/Library/Python/3.9/lib/python/site-packages/wandb/sdk/lib/retry.py", line 134, in __call__
    result = self._call_fn(*args, **kwargs)
  File "/Users/luosmallrui/Library/Python/3.9/lib/python/site-packages/wandb/sdk/internal/internal_api.py", line 402, in execute
    return self.client.execute(*args, **kwargs)  # type: ignore
  File "/Users/luosmallrui/Library/Python/3.9/lib/python/site-packages/wandb/vendor/gql-0.2.0/wandb_gql/client.py", line 52, in execute
    result = self._get_result(document, *args, **kwargs)
  File "/Users/luosmallrui/Library/Python/3.9/lib/python/site-packages/wandb/vendor/gql-0.2.0/wandb_gql/client.py", line 60, in _get_result
    return self.transport.execute(document, *args, **kwargs)
  File "/Users/luosmallrui/Library/Python/3.9/lib/python/site-packages/wandb/sdk/lib/gql_request.py", line 58, in execute
    request = self.session.post(self.url, **post_args)
  File "/Users/luosmallrui/Library/Python/3.9/lib/python/site-packages/requests/sessions.py", line 637, in post
    return self.request("POST", url, data=data, json=json, **kwargs)
  File "/Users/luosmallrui/Library/Python/3.9/lib/python/site-packages/requests/sessions.py", line 589, in request
    resp = self.send(prep, **send_kwargs)
  File "/Users/luosmallrui/Library/Python/3.9/lib/python/site-packages/requests/sessions.py", line 703, in send
    r = adapter.send(request, **kwargs)
  File "/Users/luosmallrui/Library/Python/3.9/lib/python/site-packages/requests/adapters.py", line 694, in send
    raise ProxyError(e, request=request)
requests.exceptions.ProxyError: HTTPSConnectionPool(host='api.wandb.ai', port=443): Max retries exceeded with url: /graphql (Caused by ProxyError('Cannot connect to proxy.', timeout('_ssl.c:1112: The handshake operation timed out')))
2025-07-29 00:14:04,539 INFO    MainThread:34751 [wandb_init.py:init():1014] starting run threads in backend
2025-07-29 00:14:04,786 INFO    MainThread:34751 [wandb_run.py:_console_start():2454] atexit reg
2025-07-29 00:14:04,786 INFO    MainThread:34751 [wandb_run.py:_redirect():2306] redirect: wrap_raw
2025-07-29 00:14:04,786 INFO    MainThread:34751 [wandb_run.py:_redirect():2371] Wrapping output streams.
2025-07-29 00:14:04,786 INFO    MainThread:34751 [wandb_run.py:_redirect():2394] Redirects installed.
2025-07-29 00:14:04,788 INFO    MainThread:34751 [wandb_init.py:init():1056] run started, returning control to user process
2025-07-29 00:14:05,788 INFO    MsgRouterThr:34751 [mailbox.py:close():129] [no run ID] Closing mailbox, abandoning 2 handles.
2025-07-29 00:15:13,894 INFO    Thread-2  :34751 [retry.py:__call__():175] [no run ID] Retry attempt failed:
Traceback (most recent call last):
  File "/Users/luosmallrui/Library/Python/3.9/lib/python/site-packages/urllib3/connectionpool.py", line 713, in urlopen
    self._prepare_proxy(conn)
  File "/Users/luosmallrui/Library/Python/3.9/lib/python/site-packages/urllib3/connectionpool.py", line 1015, in _prepare_proxy
    conn.connect()
  File "/Users/luosmallrui/Library/Python/3.9/lib/python/site-packages/urllib3/connection.py", line 419, in connect
    self.sock = ssl_wrap_socket(
  File "/Users/luosmallrui/Library/Python/3.9/lib/python/site-packages/urllib3/util/ssl_.py", line 458, in ssl_wrap_socket
    ssl_sock = _ssl_wrap_socket_impl(
  File "/Users/luosmallrui/Library/Python/3.9/lib/python/site-packages/urllib3/util/ssl_.py", line 502, in _ssl_wrap_socket_impl
    return ssl_context.wrap_socket(sock, server_hostname=server_hostname)
  File "/Library/Developer/CommandLineTools/Library/Frameworks/Python3.framework/Versions/3.9/lib/python3.9/ssl.py", line 500, in wrap_socket
    return self.sslsocket_class._create(
  File "/Library/Developer/CommandLineTools/Library/Frameworks/Python3.framework/Versions/3.9/lib/python3.9/ssl.py", line 1040, in _create
    self.do_handshake()
  File "/Library/Developer/CommandLineTools/Library/Frameworks/Python3.framework/Versions/3.9/lib/python3.9/ssl.py", line 1309, in do_handshake
    self._sslobj.do_handshake()
socket.timeout: _ssl.c:1112: The handshake operation timed out

During handling of the above exception, another exception occurred:

Traceback (most recent call last):
  File "/Users/luosmallrui/Library/Python/3.9/lib/python/site-packages/requests/adapters.py", line 667, in send
    resp = conn.urlopen(
  File "/Users/luosmallrui/Library/Python/3.9/lib/python/site-packages/urllib3/connectionpool.py", line 802, in urlopen
    retries = retries.increment(
  File "/Users/luosmallrui/Library/Python/3.9/lib/python/site-packages/urllib3/util/retry.py", line 594, in increment
    raise MaxRetryError(_pool, url, error or ResponseError(cause))
urllib3.exceptions.MaxRetryError: HTTPSConnectionPool(host='api.wandb.ai', port=443): Max retries exceeded with url: /graphql (Caused by ProxyError('Cannot connect to proxy.', timeout('_ssl.c:1112: The handshake operation timed out')))

During handling of the above exception, another exception occurred:

Traceback (most recent call last):
  File "/Users/luosmallrui/Library/Python/3.9/lib/python/site-packages/wandb/sdk/lib/retry.py", line 134, in __call__
    result = self._call_fn(*args, **kwargs)
  File "/Users/luosmallrui/Library/Python/3.9/lib/python/site-packages/wandb/sdk/internal/internal_api.py", line 402, in execute
    return self.client.execute(*args, **kwargs)  # type: ignore
  File "/Users/luosmallrui/Library/Python/3.9/lib/python/site-packages/wandb/vendor/gql-0.2.0/wandb_gql/client.py", line 52, in execute
    result = self._get_result(document, *args, **kwargs)
  File "/Users/luosmallrui/Library/Python/3.9/lib/python/site-packages/wandb/vendor/gql-0.2.0/wandb_gql/client.py", line 60, in _get_result
    return self.transport.execute(document, *args, **kwargs)
  File "/Users/luosmallrui/Library/Python/3.9/lib/python/site-packages/wandb/sdk/lib/gql_request.py", line 58, in execute
    request = self.session.post(self.url, **post_args)
  File "/Users/luosmallrui/Library/Python/3.9/lib/python/site-packages/requests/sessions.py", line 637, in post
    return self.request("POST", url, data=data, json=json, **kwargs)
  File "/Users/luosmallrui/Library/Python/3.9/lib/python/site-packages/requests/sessions.py", line 589, in request
    resp = self.send(prep, **send_kwargs)
  File "/Users/luosmallrui/Library/Python/3.9/lib/python/site-packages/requests/sessions.py", line 703, in send
    r = adapter.send(request, **kwargs)
  File "/Users/luosmallrui/Library/Python/3.9/lib/python/site-packages/requests/adapters.py", line 694, in send
    raise ProxyError(e, request=request)
requests.exceptions.ProxyError: HTTPSConnectionPool(host='api.wandb.ai', port=443): Max retries exceeded with url: /graphql (Caused by ProxyError('Cannot connect to proxy.', timeout('_ssl.c:1112: The handshake operation timed out')))
2025-07-29 00:15:13,900 ERROR   Thread-2  :34751 [redirect.py:_on_write():661] [no run ID] error in stderr callback
Traceback (most recent call last):
  File "/Users/luosmallrui/Library/Python/3.9/lib/python/site-packages/urllib3/connectionpool.py", line 713, in urlopen
    self._prepare_proxy(conn)
  File "/Users/luosmallrui/Library/Python/3.9/lib/python/site-packages/urllib3/connectionpool.py", line 1015, in _prepare_proxy
    conn.connect()
  File "/Users/luosmallrui/Library/Python/3.9/lib/python/site-packages/urllib3/connection.py", line 419, in connect
    self.sock = ssl_wrap_socket(
  File "/Users/luosmallrui/Library/Python/3.9/lib/python/site-packages/urllib3/util/ssl_.py", line 458, in ssl_wrap_socket
    ssl_sock = _ssl_wrap_socket_impl(
  File "/Users/luosmallrui/Library/Python/3.9/lib/python/site-packages/urllib3/util/ssl_.py", line 502, in _ssl_wrap_socket_impl
    return ssl_context.wrap_socket(sock, server_hostname=server_hostname)
  File "/Library/Developer/CommandLineTools/Library/Frameworks/Python3.framework/Versions/3.9/lib/python3.9/ssl.py", line 500, in wrap_socket
    return self.sslsocket_class._create(
  File "/Library/Developer/CommandLineTools/Library/Frameworks/Python3.framework/Versions/3.9/lib/python3.9/ssl.py", line 1040, in _create
    self.do_handshake()
  File "/Library/Developer/CommandLineTools/Library/Frameworks/Python3.framework/Versions/3.9/lib/python3.9/ssl.py", line 1309, in do_handshake
    self._sslobj.do_handshake()
socket.timeout: _ssl.c:1112: The handshake operation timed out

During handling of the above exception, another exception occurred:

Traceback (most recent call last):
  File "/Users/luosmallrui/Library/Python/3.9/lib/python/site-packages/requests/adapters.py", line 667, in send
    resp = conn.urlopen(
  File "/Users/luosmallrui/Library/Python/3.9/lib/python/site-packages/urllib3/connectionpool.py", line 802, in urlopen
    retries = retries.increment(
  File "/Users/luosmallrui/Library/Python/3.9/lib/python/site-packages/urllib3/util/retry.py", line 594, in increment
    raise MaxRetryError(_pool, url, error or ResponseError(cause))
urllib3.exceptions.MaxRetryError: HTTPSConnectionPool(host='api.wandb.ai', port=443): Max retries exceeded with url: /graphql (Caused by ProxyError('Cannot connect to proxy.', timeout('_ssl.c:1112: The handshake operation timed out')))

During handling of the above exception, another exception occurred:

Traceback (most recent call last):
  File "/Users/luosmallrui/Library/Python/3.9/lib/python/site-packages/wandb/sdk/lib/retry.py", line 134, in __call__
    result = self._call_fn(*args, **kwargs)
  File "/Users/luosmallrui/Library/Python/3.9/lib/python/site-packages/wandb/sdk/internal/internal_api.py", line 402, in execute
    return self.client.execute(*args, **kwargs)  # type: ignore
  File "/Users/luosmallrui/Library/Python/3.9/lib/python/site-packages/wandb/vendor/gql-0.2.0/wandb_gql/client.py", line 52, in execute
    result = self._get_result(document, *args, **kwargs)
  File "/Users/luosmallrui/Library/Python/3.9/lib/python/site-packages/wandb/vendor/gql-0.2.0/wandb_gql/client.py", line 60, in _get_result
    return self.transport.execute(document, *args, **kwargs)
  File "/Users/luosmallrui/Library/Python/3.9/lib/python/site-packages/wandb/sdk/lib/gql_request.py", line 58, in execute
    request = self.session.post(self.url, **post_args)
  File "/Users/luosmallrui/Library/Python/3.9/lib/python/site-packages/requests/sessions.py", line 637, in post
    return self.request("POST", url, data=data, json=json, **kwargs)
  File "/Users/luosmallrui/Library/Python/3.9/lib/python/site-packages/requests/sessions.py", line 589, in request
    resp = self.send(prep, **send_kwargs)
  File "/Users/luosmallrui/Library/Python/3.9/lib/python/site-packages/requests/sessions.py", line 703, in send
    r = adapter.send(request, **kwargs)
  File "/Users/luosmallrui/Library/Python/3.9/lib/python/site-packages/requests/adapters.py", line 694, in send
    raise ProxyError(e, request=request)
requests.exceptions.ProxyError: HTTPSConnectionPool(host='api.wandb.ai', port=443): Max retries exceeded with url: /graphql (Caused by ProxyError('Cannot connect to proxy.', timeout('_ssl.c:1112: The handshake operation timed out')))

During handling of the above exception, another exception occurred:

Traceback (most recent call last):
  File "/Users/luosmallrui/Library/Python/3.9/lib/python/site-packages/wandb/sdk/lib/redirect.py", line 659, in _on_write
    cb(written_data)
  File "/Users/luosmallrui/Library/Python/3.9/lib/python/site-packages/wandb/sdk/wandb_run.py", line 2381, in <lambda>
    lambda data: self._console_raw_callback("stderr", data),
  File "/Users/luosmallrui/Library/Python/3.9/lib/python/site-packages/wandb/sdk/wandb_run.py", line 387, in wrapper
    return func(self, *args, **kwargs)
  File "/Users/luosmallrui/Library/Python/3.9/lib/python/site-packages/wandb/sdk/wandb_run.py", line 435, in wrapper_fn
    return func(self, *args, **kwargs)
  File "/Users/luosmallrui/Library/Python/3.9/lib/python/site-packages/wandb/sdk/wandb_run.py", line 1518, in _console_raw_callback
    self._backend.interface.publish_output_raw(name, data)
  File "/Users/luosmallrui/Library/Python/3.9/lib/python/site-packages/wandb/sdk/interface/interface.py", line 761, in publish_output_raw
    self._publish_output_raw(o)
  File "/Users/luosmallrui/Library/Python/3.9/lib/python/site-packages/wandb/sdk/interface/interface_shared.py", line 38, in _publish_output_raw
    self._publish(rec)
  File "/Users/luosmallrui/Library/Python/3.9/lib/python/site-packages/wandb/sdk/interface/interface_sock.py", line 39, in _publish
    self._sock_client.send_record_publish(record)
  File "/Users/luosmallrui/Library/Python/3.9/lib/python/site-packages/wandb/sdk/lib/sock_client.py", line 174, in send_record_publish
    self.send_server_request(server_req)
  File "/Users/luosmallrui/Library/Python/3.9/lib/python/site-packages/wandb/sdk/lib/sock_client.py", line 154, in send_server_request
    self._send_message(msg)
  File "/Users/luosmallrui/Library/Python/3.9/lib/python/site-packages/wandb/sdk/lib/sock_client.py", line 151, in _send_message
    self._sendall_with_error_handle(header + data)
  File "/Users/luosmallrui/Library/Python/3.9/lib/python/site-packages/wandb/sdk/lib/sock_client.py", line 130, in _sendall_with_error_handle
    sent = self._sock.send(data)
BrokenPipeError: [Errno 32] Broken pipe
2025-07-29 00:15:23,541 INFO    Thread-4  :34751 [retry.py:__call__():175] [no run ID] Retry attempt failed:
Traceback (most recent call last):
  File "/Users/luosmallrui/Library/Python/3.9/lib/python/site-packages/urllib3/connectionpool.py", line 713, in urlopen
    self._prepare_proxy(conn)
  File "/Users/luosmallrui/Library/Python/3.9/lib/python/site-packages/urllib3/connectionpool.py", line 1015, in _prepare_proxy
    conn.connect()
  File "/Users/luosmallrui/Library/Python/3.9/lib/python/site-packages/urllib3/connection.py", line 419, in connect
    self.sock = ssl_wrap_socket(
  File "/Users/luosmallrui/Library/Python/3.9/lib/python/site-packages/urllib3/util/ssl_.py", line 458, in ssl_wrap_socket
    ssl_sock = _ssl_wrap_socket_impl(
  File "/Users/luosmallrui/Library/Python/3.9/lib/python/site-packages/urllib3/util/ssl_.py", line 502, in _ssl_wrap_socket_impl
    return ssl_context.wrap_socket(sock, server_hostname=server_hostname)
  File "/Library/Developer/CommandLineTools/Library/Frameworks/Python3.framework/Versions/3.9/lib/python3.9/ssl.py", line 500, in wrap_socket
    return self.sslsocket_class._create(
  File "/Library/Developer/CommandLineTools/Library/Frameworks/Python3.framework/Versions/3.9/lib/python3.9/ssl.py", line 1040, in _create
    self.do_handshake()
  File "/Library/Developer/CommandLineTools/Library/Frameworks/Python3.framework/Versions/3.9/lib/python3.9/ssl.py", line 1309, in do_handshake
    self._sslobj.do_handshake()
socket.timeout: _ssl.c:1112: The handshake operation timed out

During handling of the above exception, another exception occurred:

Traceback (most recent call last):
  File "/Users/luosmallrui/Library/Python/3.9/lib/python/site-packages/requests/adapters.py", line 667, in send
    resp = conn.urlopen(
  File "/Users/luosmallrui/Library/Python/3.9/lib/python/site-packages/urllib3/connectionpool.py", line 802, in urlopen
    retries = retries.increment(
  File "/Users/luosmallrui/Library/Python/3.9/lib/python/site-packages/urllib3/util/retry.py", line 594, in increment
    raise MaxRetryError(_pool, url, error or ResponseError(cause))
urllib3.exceptions.MaxRetryError: HTTPSConnectionPool(host='api.wandb.ai', port=443): Max retries exceeded with url: /graphql (Caused by ProxyError('Cannot connect to proxy.', timeout('_ssl.c:1112: The handshake operation timed out')))

During handling of the above exception, another exception occurred:

Traceback (most recent call last):
  File "/Users/luosmallrui/Library/Python/3.9/lib/python/site-packages/wandb/sdk/lib/retry.py", line 134, in __call__
    result = self._call_fn(*args, **kwargs)
  File "/Users/luosmallrui/Library/Python/3.9/lib/python/site-packages/wandb/sdk/internal/internal_api.py", line 402, in execute
    return self.client.execute(*args, **kwargs)  # type: ignore
  File "/Users/luosmallrui/Library/Python/3.9/lib/python/site-packages/wandb/vendor/gql-0.2.0/wandb_gql/client.py", line 52, in execute
    result = self._get_result(document, *args, **kwargs)
  File "/Users/luosmallrui/Library/Python/3.9/lib/python/site-packages/wandb/vendor/gql-0.2.0/wandb_gql/client.py", line 60, in _get_result
    return self.transport.execute(document, *args, **kwargs)
  File "/Users/luosmallrui/Library/Python/3.9/lib/python/site-packages/wandb/sdk/lib/gql_request.py", line 58, in execute
    request = self.session.post(self.url, **post_args)
  File "/Users/luosmallrui/Library/Python/3.9/lib/python/site-packages/requests/sessions.py", line 637, in post
    return self.request("POST", url, data=data, json=json, **kwargs)
  File "/Users/luosmallrui/Library/Python/3.9/lib/python/site-packages/requests/sessions.py", line 589, in request
    resp = self.send(prep, **send_kwargs)
  File "/Users/luosmallrui/Library/Python/3.9/lib/python/site-packages/requests/sessions.py", line 703, in send
    r = adapter.send(request, **kwargs)
  File "/Users/luosmallrui/Library/Python/3.9/lib/python/site-packages/requests/adapters.py", line 694, in send
    raise ProxyError(e, request=request)
requests.exceptions.ProxyError: HTTPSConnectionPool(host='api.wandb.ai', port=443): Max retries exceeded with url: /graphql (Caused by ProxyError('Cannot connect to proxy.', timeout('_ssl.c:1112: The handshake operation timed out')))
2025-07-29 00:15:23,542 ERROR   Thread-4  :34751 [redirect.py:_on_write():661] [no run ID] error in stderr callback
Traceback (most recent call last):
  File "/Users/luosmallrui/Library/Python/3.9/lib/python/site-packages/urllib3/connectionpool.py", line 713, in urlopen
    self._prepare_proxy(conn)
  File "/Users/luosmallrui/Library/Python/3.9/lib/python/site-packages/urllib3/connectionpool.py", line 1015, in _prepare_proxy
    conn.connect()
  File "/Users/luosmallrui/Library/Python/3.9/lib/python/site-packages/urllib3/connection.py", line 419, in connect
    self.sock = ssl_wrap_socket(
  File "/Users/luosmallrui/Library/Python/3.9/lib/python/site-packages/urllib3/util/ssl_.py", line 458, in ssl_wrap_socket
    ssl_sock = _ssl_wrap_socket_impl(
  File "/Users/luosmallrui/Library/Python/3.9/lib/python/site-packages/urllib3/util/ssl_.py", line 502, in _ssl_wrap_socket_impl
    return ssl_context.wrap_socket(sock, server_hostname=server_hostname)
  File "/Library/Developer/CommandLineTools/Library/Frameworks/Python3.framework/Versions/3.9/lib/python3.9/ssl.py", line 500, in wrap_socket
    return self.sslsocket_class._create(
  File "/Library/Developer/CommandLineTools/Library/Frameworks/Python3.framework/Versions/3.9/lib/python3.9/ssl.py", line 1040, in _create
    self.do_handshake()
  File "/Library/Developer/CommandLineTools/Library/Frameworks/Python3.framework/Versions/3.9/lib/python3.9/ssl.py", line 1309, in do_handshake
    self._sslobj.do_handshake()
socket.timeout: _ssl.c:1112: The handshake operation timed out

During handling of the above exception, another exception occurred:

Traceback (most recent call last):
  File "/Users/luosmallrui/Library/Python/3.9/lib/python/site-packages/requests/adapters.py", line 667, in send
    resp = conn.urlopen(
  File "/Users/luosmallrui/Library/Python/3.9/lib/python/site-packages/urllib3/connectionpool.py", line 802, in urlopen
    retries = retries.increment(
  File "/Users/luosmallrui/Library/Python/3.9/lib/python/site-packages/urllib3/util/retry.py", line 594, in increment
    raise MaxRetryError(_pool, url, error or ResponseError(cause))
urllib3.exceptions.MaxRetryError: HTTPSConnectionPool(host='api.wandb.ai', port=443): Max retries exceeded with url: /graphql (Caused by ProxyError('Cannot connect to proxy.', timeout('_ssl.c:1112: The handshake operation timed out')))

During handling of the above exception, another exception occurred:

Traceback (most recent call last):
  File "/Users/luosmallrui/Library/Python/3.9/lib/python/site-packages/wandb/sdk/lib/retry.py", line 134, in __call__
    result = self._call_fn(*args, **kwargs)
  File "/Users/luosmallrui/Library/Python/3.9/lib/python/site-packages/wandb/sdk/internal/internal_api.py", line 402, in execute
    return self.client.execute(*args, **kwargs)  # type: ignore
  File "/Users/luosmallrui/Library/Python/3.9/lib/python/site-packages/wandb/vendor/gql-0.2.0/wandb_gql/client.py", line 52, in execute
    result = self._get_result(document, *args, **kwargs)
  File "/Users/luosmallrui/Library/Python/3.9/lib/python/site-packages/wandb/vendor/gql-0.2.0/wandb_gql/client.py", line 60, in _get_result
    return self.transport.execute(document, *args, **kwargs)
  File "/Users/luosmallrui/Library/Python/3.9/lib/python/site-packages/wandb/sdk/lib/gql_request.py", line 58, in execute
    request = self.session.post(self.url, **post_args)
  File "/Users/luosmallrui/Library/Python/3.9/lib/python/site-packages/requests/sessions.py", line 637, in post
    return self.request("POST", url, data=data, json=json, **kwargs)
  File "/Users/luosmallrui/Library/Python/3.9/lib/python/site-packages/requests/sessions.py", line 589, in request
    resp = self.send(prep, **send_kwargs)
  File "/Users/luosmallrui/Library/Python/3.9/lib/python/site-packages/requests/sessions.py", line 703, in send
    r = adapter.send(request, **kwargs)
  File "/Users/luosmallrui/Library/Python/3.9/lib/python/site-packages/requests/adapters.py", line 694, in send
    raise ProxyError(e, request=request)
requests.exceptions.ProxyError: HTTPSConnectionPool(host='api.wandb.ai', port=443): Max retries exceeded with url: /graphql (Caused by ProxyError('Cannot connect to proxy.', timeout('_ssl.c:1112: The handshake operation timed out')))

During handling of the above exception, another exception occurred:

Traceback (most recent call last):
  File "/Users/luosmallrui/Library/Python/3.9/lib/python/site-packages/wandb/sdk/lib/redirect.py", line 659, in _on_write
    cb(written_data)
  File "/Users/luosmallrui/Library/Python/3.9/lib/python/site-packages/wandb/sdk/wandb_run.py", line 2381, in <lambda>
    lambda data: self._console_raw_callback("stderr", data),
  File "/Users/luosmallrui/Library/Python/3.9/lib/python/site-packages/wandb/sdk/wandb_run.py", line 387, in wrapper
    return func(self, *args, **kwargs)
  File "/Users/luosmallrui/Library/Python/3.9/lib/python/site-packages/wandb/sdk/wandb_run.py", line 435, in wrapper_fn
    return func(self, *args, **kwargs)
  File "/Users/luosmallrui/Library/Python/3.9/lib/python/site-packages/wandb/sdk/wandb_run.py", line 1518, in _console_raw_callback
    self._backend.interface.publish_output_raw(name, data)
  File "/Users/luosmallrui/Library/Python/3.9/lib/python/site-packages/wandb/sdk/interface/interface.py", line 761, in publish_output_raw
    self._publish_output_raw(o)
  File "/Users/luosmallrui/Library/Python/3.9/lib/python/site-packages/wandb/sdk/interface/interface_shared.py", line 38, in _publish_output_raw
    self._publish(rec)
  File "/Users/luosmallrui/Library/Python/3.9/lib/python/site-packages/wandb/sdk/interface/interface_sock.py", line 39, in _publish
    self._sock_client.send_record_publish(record)
  File "/Users/luosmallrui/Library/Python/3.9/lib/python/site-packages/wandb/sdk/lib/sock_client.py", line 174, in send_record_publish
    self.send_server_request(server_req)
  File "/Users/luosmallrui/Library/Python/3.9/lib/python/site-packages/wandb/sdk/lib/sock_client.py", line 154, in send_server_request
    self._send_message(msg)
  File "/Users/luosmallrui/Library/Python/3.9/lib/python/site-packages/wandb/sdk/lib/sock_client.py", line 151, in _send_message
    self._sendall_with_error_handle(header + data)
  File "/Users/luosmallrui/Library/Python/3.9/lib/python/site-packages/wandb/sdk/lib/sock_client.py", line 130, in _sendall_with_error_handle
    sent = self._sock.send(data)
BrokenPipeError: [Errno 32] Broken pipe
2025-07-29 00:16:49,991 ERROR   MainThread:34751 [redirect.py:_on_write():661] [no run ID] error in stderr callback
Traceback (most recent call last):
  File "/Users/luosmallrui/Library/Python/3.9/lib/python/site-packages/wandb/sdk/lib/redirect.py", line 659, in _on_write
    cb(written_data)
  File "/Users/luosmallrui/Library/Python/3.9/lib/python/site-packages/wandb/sdk/wandb_run.py", line 2381, in <lambda>
    lambda data: self._console_raw_callback("stderr", data),
  File "/Users/luosmallrui/Library/Python/3.9/lib/python/site-packages/wandb/sdk/wandb_run.py", line 387, in wrapper
    return func(self, *args, **kwargs)
  File "/Users/luosmallrui/Library/Python/3.9/lib/python/site-packages/wandb/sdk/wandb_run.py", line 435, in wrapper_fn
    return func(self, *args, **kwargs)
  File "/Users/luosmallrui/Library/Python/3.9/lib/python/site-packages/wandb/sdk/wandb_run.py", line 1518, in _console_raw_callback
    self._backend.interface.publish_output_raw(name, data)
  File "/Users/luosmallrui/Library/Python/3.9/lib/python/site-packages/wandb/sdk/interface/interface.py", line 761, in publish_output_raw
    self._publish_output_raw(o)
  File "/Users/luosmallrui/Library/Python/3.9/lib/python/site-packages/wandb/sdk/interface/interface_shared.py", line 38, in _publish_output_raw
    self._publish(rec)
  File "/Users/luosmallrui/Library/Python/3.9/lib/python/site-packages/wandb/sdk/interface/interface_sock.py", line 39, in _publish
    self._sock_client.send_record_publish(record)
  File "/Users/luosmallrui/Library/Python/3.9/lib/python/site-packages/wandb/sdk/lib/sock_client.py", line 174, in send_record_publish
    self.send_server_request(server_req)
  File "/Users/luosmallrui/Library/Python/3.9/lib/python/site-packages/wandb/sdk/lib/sock_client.py", line 154, in send_server_request
    self._send_message(msg)
  File "/Users/luosmallrui/Library/Python/3.9/lib/python/site-packages/wandb/sdk/lib/sock_client.py", line 151, in _send_message
    self._sendall_with_error_handle(header + data)
  File "/Users/luosmallrui/Library/Python/3.9/lib/python/site-packages/wandb/sdk/lib/sock_client.py", line 130, in _sendall_with_error_handle
    sent = self._sock.send(data)
BrokenPipeError: [Errno 32] Broken pipe
2025-07-29 00:16:49,996 ERROR   MainThread:34751 [redirect.py:_on_write():661] [no run ID] error in stderr callback
Traceback (most recent call last):
  File "/Users/luosmallrui/Library/Python/3.9/lib/python/site-packages/wandb/sdk/lib/redirect.py", line 659, in _on_write
    cb(written_data)
  File "/Users/luosmallrui/Library/Python/3.9/lib/python/site-packages/wandb/sdk/wandb_run.py", line 2381, in <lambda>
    lambda data: self._console_raw_callback("stderr", data),
  File "/Users/luosmallrui/Library/Python/3.9/lib/python/site-packages/wandb/sdk/wandb_run.py", line 387, in wrapper
    return func(self, *args, **kwargs)
  File "/Users/luosmallrui/Library/Python/3.9/lib/python/site-packages/wandb/sdk/wandb_run.py", line 435, in wrapper_fn
    return func(self, *args, **kwargs)
  File "/Users/luosmallrui/Library/Python/3.9/lib/python/site-packages/wandb/sdk/wandb_run.py", line 1518, in _console_raw_callback
    self._backend.interface.publish_output_raw(name, data)
  File "/Users/luosmallrui/Library/Python/3.9/lib/python/site-packages/wandb/sdk/interface/interface.py", line 761, in publish_output_raw
    self._publish_output_raw(o)
  File "/Users/luosmallrui/Library/Python/3.9/lib/python/site-packages/wandb/sdk/interface/interface_shared.py", line 38, in _publish_output_raw
    self._publish(rec)
  File "/Users/luosmallrui/Library/Python/3.9/lib/python/site-packages/wandb/sdk/interface/interface_sock.py", line 39, in _publish
    self._sock_client.send_record_publish(record)
  File "/Users/luosmallrui/Library/Python/3.9/lib/python/site-packages/wandb/sdk/lib/sock_client.py", line 174, in send_record_publish
    self.send_server_request(server_req)
  File "/Users/luosmallrui/Library/Python/3.9/lib/python/site-packages/wandb/sdk/lib/sock_client.py", line 154, in send_server_request
    self._send_message(msg)
  File "/Users/luosmallrui/Library/Python/3.9/lib/python/site-packages/wandb/sdk/lib/sock_client.py", line 151, in _send_message
    self._sendall_with_error_handle(header + data)
  File "/Users/luosmallrui/Library/Python/3.9/lib/python/site-packages/wandb/sdk/lib/sock_client.py", line 130, in _sendall_with_error_handle
    sent = self._sock.send(data)
BrokenPipeError: [Errno 32] Broken pipe
2025-07-29 00:16:49,997 ERROR   MainThread:34751 [redirect.py:_on_write():661] [no run ID] error in stderr callback
Traceback (most recent call last):
  File "/Users/luosmallrui/Library/Python/3.9/lib/python/site-packages/wandb/sdk/lib/redirect.py", line 659, in _on_write
    cb(written_data)
  File "/Users/luosmallrui/Library/Python/3.9/lib/python/site-packages/wandb/sdk/wandb_run.py", line 2381, in <lambda>
    lambda data: self._console_raw_callback("stderr", data),
  File "/Users/luosmallrui/Library/Python/3.9/lib/python/site-packages/wandb/sdk/wandb_run.py", line 387, in wrapper
    return func(self, *args, **kwargs)
  File "/Users/luosmallrui/Library/Python/3.9/lib/python/site-packages/wandb/sdk/wandb_run.py", line 435, in wrapper_fn
    return func(self, *args, **kwargs)
  File "/Users/luosmallrui/Library/Python/3.9/lib/python/site-packages/wandb/sdk/wandb_run.py", line 1518, in _console_raw_callback
    self._backend.interface.publish_output_raw(name, data)
  File "/Users/luosmallrui/Library/Python/3.9/lib/python/site-packages/wandb/sdk/interface/interface.py", line 761, in publish_output_raw
    self._publish_output_raw(o)
  File "/Users/luosmallrui/Library/Python/3.9/lib/python/site-packages/wandb/sdk/interface/interface_shared.py", line 38, in _publish_output_raw
    self._publish(rec)
  File "/Users/luosmallrui/Library/Python/3.9/lib/python/site-packages/wandb/sdk/interface/interface_sock.py", line 39, in _publish
    self._sock_client.send_record_publish(record)
  File "/Users/luosmallrui/Library/Python/3.9/lib/python/site-packages/wandb/sdk/lib/sock_client.py", line 174, in send_record_publish
    self.send_server_request(server_req)
  File "/Users/luosmallrui/Library/Python/3.9/lib/python/site-packages/wandb/sdk/lib/sock_client.py", line 154, in send_server_request
    self._send_message(msg)
  File "/Users/luosmallrui/Library/Python/3.9/lib/python/site-packages/wandb/sdk/lib/sock_client.py", line 151, in _send_message
    self._sendall_with_error_handle(header + data)
  File "/Users/luosmallrui/Library/Python/3.9/lib/python/site-packages/wandb/sdk/lib/sock_client.py", line 130, in _sendall_with_error_handle
    sent = self._sock.send(data)
BrokenPipeError: [Errno 32] Broken pipe
2025-07-29 00:16:50,000 ERROR   MainThread:34751 [redirect.py:_on_write():661] [no run ID] error in stderr callback
Traceback (most recent call last):
  File "/Users/luosmallrui/Library/Python/3.9/lib/python/site-packages/wandb/sdk/lib/redirect.py", line 659, in _on_write
    cb(written_data)
  File "/Users/luosmallrui/Library/Python/3.9/lib/python/site-packages/wandb/sdk/wandb_run.py", line 2381, in <lambda>
    lambda data: self._console_raw_callback("stderr", data),
  File "/Users/luosmallrui/Library/Python/3.9/lib/python/site-packages/wandb/sdk/wandb_run.py", line 387, in wrapper
    return func(self, *args, **kwargs)
  File "/Users/luosmallrui/Library/Python/3.9/lib/python/site-packages/wandb/sdk/wandb_run.py", line 435, in wrapper_fn
    return func(self, *args, **kwargs)
  File "/Users/luosmallrui/Library/Python/3.9/lib/python/site-packages/wandb/sdk/wandb_run.py", line 1518, in _console_raw_callback
    self._backend.interface.publish_output_raw(name, data)
  File "/Users/luosmallrui/Library/Python/3.9/lib/python/site-packages/wandb/sdk/interface/interface.py", line 761, in publish_output_raw
    self._publish_output_raw(o)
  File "/Users/luosmallrui/Library/Python/3.9/lib/python/site-packages/wandb/sdk/interface/interface_shared.py", line 38, in _publish_output_raw
    self._publish(rec)
  File "/Users/luosmallrui/Library/Python/3.9/lib/python/site-packages/wandb/sdk/interface/interface_sock.py", line 39, in _publish
    self._sock_client.send_record_publish(record)
  File "/Users/luosmallrui/Library/Python/3.9/lib/python/site-packages/wandb/sdk/lib/sock_client.py", line 174, in send_record_publish
    self.send_server_request(server_req)
  File "/Users/luosmallrui/Library/Python/3.9/lib/python/site-packages/wandb/sdk/lib/sock_client.py", line 154, in send_server_request
    self._send_message(msg)
  File "/Users/luosmallrui/Library/Python/3.9/lib/python/site-packages/wandb/sdk/lib/sock_client.py", line 151, in _send_message
    self._sendall_with_error_handle(header + data)
  File "/Users/luosmallrui/Library/Python/3.9/lib/python/site-packages/wandb/sdk/lib/sock_client.py", line 130, in _sendall_with_error_handle
    sent = self._sock.send(data)
BrokenPipeError: [Errno 32] Broken pipe
2025-07-29 00:16:50,000 ERROR   MainThread:34751 [redirect.py:_on_write():661] [no run ID] error in stderr callback
Traceback (most recent call last):
  File "/Users/luosmallrui/Library/Python/3.9/lib/python/site-packages/wandb/sdk/lib/redirect.py", line 659, in _on_write
    cb(written_data)
  File "/Users/luosmallrui/Library/Python/3.9/lib/python/site-packages/wandb/sdk/wandb_run.py", line 2381, in <lambda>
    lambda data: self._console_raw_callback("stderr", data),
  File "/Users/luosmallrui/Library/Python/3.9/lib/python/site-packages/wandb/sdk/wandb_run.py", line 387, in wrapper
    return func(self, *args, **kwargs)
  File "/Users/luosmallrui/Library/Python/3.9/lib/python/site-packages/wandb/sdk/wandb_run.py", line 435, in wrapper_fn
    return func(self, *args, **kwargs)
  File "/Users/luosmallrui/Library/Python/3.9/lib/python/site-packages/wandb/sdk/wandb_run.py", line 1518, in _console_raw_callback
    self._backend.interface.publish_output_raw(name, data)
  File "/Users/luosmallrui/Library/Python/3.9/lib/python/site-packages/wandb/sdk/interface/interface.py", line 761, in publish_output_raw
    self._publish_output_raw(o)
  File "/Users/luosmallrui/Library/Python/3.9/lib/python/site-packages/wandb/sdk/interface/interface_shared.py", line 38, in _publish_output_raw
    self._publish(rec)
  File "/Users/luosmallrui/Library/Python/3.9/lib/python/site-packages/wandb/sdk/interface/interface_sock.py", line 39, in _publish
    self._sock_client.send_record_publish(record)
  File "/Users/luosmallrui/Library/Python/3.9/lib/python/site-packages/wandb/sdk/lib/sock_client.py", line 174, in send_record_publish
    self.send_server_request(server_req)
  File "/Users/luosmallrui/Library/Python/3.9/lib/python/site-packages/wandb/sdk/lib/sock_client.py", line 154, in send_server_request
    self._send_message(msg)
  File "/Users/luosmallrui/Library/Python/3.9/lib/python/site-packages/wandb/sdk/lib/sock_client.py", line 151, in _send_message
    self._sendall_with_error_handle(header + data)
  File "/Users/luosmallrui/Library/Python/3.9/lib/python/site-packages/wandb/sdk/lib/sock_client.py", line 130, in _sendall_with_error_handle
    sent = self._sock.send(data)
BrokenPipeError: [Errno 32] Broken pipe
2025-07-29 00:16:50,000 ERROR   MainThread:34751 [redirect.py:_on_write():661] [no run ID] error in stderr callback
Traceback (most recent call last):
  File "/Users/luosmallrui/Library/Python/3.9/lib/python/site-packages/wandb/sdk/lib/redirect.py", line 659, in _on_write
    cb(written_data)
  File "/Users/luosmallrui/Library/Python/3.9/lib/python/site-packages/wandb/sdk/wandb_run.py", line 2381, in <lambda>
    lambda data: self._console_raw_callback("stderr", data),
  File "/Users/luosmallrui/Library/Python/3.9/lib/python/site-packages/wandb/sdk/wandb_run.py", line 387, in wrapper
    return func(self, *args, **kwargs)
  File "/Users/luosmallrui/Library/Python/3.9/lib/python/site-packages/wandb/sdk/wandb_run.py", line 435, in wrapper_fn
    return func(self, *args, **kwargs)
  File "/Users/luosmallrui/Library/Python/3.9/lib/python/site-packages/wandb/sdk/wandb_run.py", line 1518, in _console_raw_callback
    self._backend.interface.publish_output_raw(name, data)
  File "/Users/luosmallrui/Library/Python/3.9/lib/python/site-packages/wandb/sdk/interface/interface.py", line 761, in publish_output_raw
    self._publish_output_raw(o)
  File "/Users/luosmallrui/Library/Python/3.9/lib/python/site-packages/wandb/sdk/interface/interface_shared.py", line 38, in _publish_output_raw
    self._publish(rec)
  File "/Users/luosmallrui/Library/Python/3.9/lib/python/site-packages/wandb/sdk/interface/interface_sock.py", line 39, in _publish
    self._sock_client.send_record_publish(record)
  File "/Users/luosmallrui/Library/Python/3.9/lib/python/site-packages/wandb/sdk/lib/sock_client.py", line 174, in send_record_publish
    self.send_server_request(server_req)
  File "/Users/luosmallrui/Library/Python/3.9/lib/python/site-packages/wandb/sdk/lib/sock_client.py", line 154, in send_server_request
    self._send_message(msg)
  File "/Users/luosmallrui/Library/Python/3.9/lib/python/site-packages/wandb/sdk/lib/sock_client.py", line 151, in _send_message
    self._sendall_with_error_handle(header + data)
  File "/Users/luosmallrui/Library/Python/3.9/lib/python/site-packages/wandb/sdk/lib/sock_client.py", line 130, in _sendall_with_error_handle
    sent = self._sock.send(data)
BrokenPipeError: [Errno 32] Broken pipe
2025-07-29 00:16:50,000 ERROR   MainThread:34751 [redirect.py:_on_write():661] [no run ID] error in stderr callback
Traceback (most recent call last):
  File "/Users/luosmallrui/Library/Python/3.9/lib/python/site-packages/wandb/sdk/lib/redirect.py", line 659, in _on_write
    cb(written_data)
  File "/Users/luosmallrui/Library/Python/3.9/lib/python/site-packages/wandb/sdk/wandb_run.py", line 2381, in <lambda>
    lambda data: self._console_raw_callback("stderr", data),
  File "/Users/luosmallrui/Library/Python/3.9/lib/python/site-packages/wandb/sdk/wandb_run.py", line 387, in wrapper
    return func(self, *args, **kwargs)
  File "/Users/luosmallrui/Library/Python/3.9/lib/python/site-packages/wandb/sdk/wandb_run.py", line 435, in wrapper_fn
    return func(self, *args, **kwargs)
  File "/Users/luosmallrui/Library/Python/3.9/lib/python/site-packages/wandb/sdk/wandb_run.py", line 1518, in _console_raw_callback
    self._backend.interface.publish_output_raw(name, data)
  File "/Users/luosmallrui/Library/Python/3.9/lib/python/site-packages/wandb/sdk/interface/interface.py", line 761, in publish_output_raw
    self._publish_output_raw(o)
  File "/Users/luosmallrui/Library/Python/3.9/lib/python/site-packages/wandb/sdk/interface/interface_shared.py", line 38, in _publish_output_raw
    self._publish(rec)
  File "/Users/luosmallrui/Library/Python/3.9/lib/python/site-packages/wandb/sdk/interface/interface_sock.py", line 39, in _publish
    self._sock_client.send_record_publish(record)
  File "/Users/luosmallrui/Library/Python/3.9/lib/python/site-packages/wandb/sdk/lib/sock_client.py", line 174, in send_record_publish
    self.send_server_request(server_req)
  File "/Users/luosmallrui/Library/Python/3.9/lib/python/site-packages/wandb/sdk/lib/sock_client.py", line 154, in send_server_request
    self._send_message(msg)
  File "/Users/luosmallrui/Library/Python/3.9/lib/python/site-packages/wandb/sdk/lib/sock_client.py", line 151, in _send_message
    self._sendall_with_error_handle(header + data)
  File "/Users/luosmallrui/Library/Python/3.9/lib/python/site-packages/wandb/sdk/lib/sock_client.py", line 130, in _sendall_with_error_handle
    sent = self._sock.send(data)
BrokenPipeError: [Errno 32] Broken pipe
2025-07-29 00:16:50,000 ERROR   MainThread:34751 [redirect.py:_on_write():661] [no run ID] error in stderr callback
Traceback (most recent call last):
  File "/Users/luosmallrui/Library/Python/3.9/lib/python/site-packages/wandb/sdk/lib/redirect.py", line 659, in _on_write
    cb(written_data)
  File "/Users/luosmallrui/Library/Python/3.9/lib/python/site-packages/wandb/sdk/wandb_run.py", line 2381, in <lambda>
    lambda data: self._console_raw_callback("stderr", data),
  File "/Users/luosmallrui/Library/Python/3.9/lib/python/site-packages/wandb/sdk/wandb_run.py", line 387, in wrapper
    return func(self, *args, **kwargs)
  File "/Users/luosmallrui/Library/Python/3.9/lib/python/site-packages/wandb/sdk/wandb_run.py", line 435, in wrapper_fn
    return func(self, *args, **kwargs)
  File "/Users/luosmallrui/Library/Python/3.9/lib/python/site-packages/wandb/sdk/wandb_run.py", line 1518, in _console_raw_callback
    self._backend.interface.publish_output_raw(name, data)
  File "/Users/luosmallrui/Library/Python/3.9/lib/python/site-packages/wandb/sdk/interface/interface.py", line 761, in publish_output_raw
    self._publish_output_raw(o)
  File "/Users/luosmallrui/Library/Python/3.9/lib/python/site-packages/wandb/sdk/interface/interface_shared.py", line 38, in _publish_output_raw
    self._publish(rec)
  File "/Users/luosmallrui/Library/Python/3.9/lib/python/site-packages/wandb/sdk/interface/interface_sock.py", line 39, in _publish
    self._sock_client.send_record_publish(record)
  File "/Users/luosmallrui/Library/Python/3.9/lib/python/site-packages/wandb/sdk/lib/sock_client.py", line 174, in send_record_publish
    self.send_server_request(server_req)
  File "/Users/luosmallrui/Library/Python/3.9/lib/python/site-packages/wandb/sdk/lib/sock_client.py", line 154, in send_server_request
    self._send_message(msg)
  File "/Users/luosmallrui/Library/Python/3.9/lib/python/site-packages/wandb/sdk/lib/sock_client.py", line 151, in _send_message
    self._sendall_with_error_handle(header + data)
  File "/Users/luosmallrui/Library/Python/3.9/lib/python/site-packages/wandb/sdk/lib/sock_client.py", line 130, in _sendall_with_error_handle
    sent = self._sock.send(data)
BrokenPipeError: [Errno 32] Broken pipe
2025-07-29 00:16:50,001 ERROR   MainThread:34751 [redirect.py:_on_write():661] [no run ID] error in stderr callback
Traceback (most recent call last):
  File "/Users/luosmallrui/Library/Python/3.9/lib/python/site-packages/wandb/sdk/lib/redirect.py", line 659, in _on_write
    cb(written_data)
  File "/Users/luosmallrui/Library/Python/3.9/lib/python/site-packages/wandb/sdk/wandb_run.py", line 2381, in <lambda>
    lambda data: self._console_raw_callback("stderr", data),
  File "/Users/luosmallrui/Library/Python/3.9/lib/python/site-packages/wandb/sdk/wandb_run.py", line 387, in wrapper
    return func(self, *args, **kwargs)
  File "/Users/luosmallrui/Library/Python/3.9/lib/python/site-packages/wandb/sdk/wandb_run.py", line 435, in wrapper_fn
    return func(self, *args, **kwargs)
  File "/Users/luosmallrui/Library/Python/3.9/lib/python/site-packages/wandb/sdk/wandb_run.py", line 1518, in _console_raw_callback
    self._backend.interface.publish_output_raw(name, data)
  File "/Users/luosmallrui/Library/Python/3.9/lib/python/site-packages/wandb/sdk/interface/interface.py", line 761, in publish_output_raw
    self._publish_output_raw(o)
  File "/Users/luosmallrui/Library/Python/3.9/lib/python/site-packages/wandb/sdk/interface/interface_shared.py", line 38, in _publish_output_raw
    self._publish(rec)
  File "/Users/luosmallrui/Library/Python/3.9/lib/python/site-packages/wandb/sdk/interface/interface_sock.py", line 39, in _publish
    self._sock_client.send_record_publish(record)
  File "/Users/luosmallrui/Library/Python/3.9/lib/python/site-packages/wandb/sdk/lib/sock_client.py", line 174, in send_record_publish
    self.send_server_request(server_req)
  File "/Users/luosmallrui/Library/Python/3.9/lib/python/site-packages/wandb/sdk/lib/sock_client.py", line 154, in send_server_request
    self._send_message(msg)
  File "/Users/luosmallrui/Library/Python/3.9/lib/python/site-packages/wandb/sdk/lib/sock_client.py", line 151, in _send_message
    self._sendall_with_error_handle(header + data)
  File "/Users/luosmallrui/Library/Python/3.9/lib/python/site-packages/wandb/sdk/lib/sock_client.py", line 130, in _sendall_with_error_handle
    sent = self._sock.send(data)
BrokenPipeError: [Errno 32] Broken pipe
2025-07-29 00:16:50,001 ERROR   MainThread:34751 [redirect.py:_on_write():661] [no run ID] error in stderr callback
Traceback (most recent call last):
  File "/Users/luosmallrui/Library/Python/3.9/lib/python/site-packages/wandb/sdk/lib/redirect.py", line 659, in _on_write
    cb(written_data)
  File "/Users/luosmallrui/Library/Python/3.9/lib/python/site-packages/wandb/sdk/wandb_run.py", line 2381, in <lambda>
    lambda data: self._console_raw_callback("stderr", data),
  File "/Users/luosmallrui/Library/Python/3.9/lib/python/site-packages/wandb/sdk/wandb_run.py", line 387, in wrapper
    return func(self, *args, **kwargs)
  File "/Users/luosmallrui/Library/Python/3.9/lib/python/site-packages/wandb/sdk/wandb_run.py", line 435, in wrapper_fn
    return func(self, *args, **kwargs)
  File "/Users/luosmallrui/Library/Python/3.9/lib/python/site-packages/wandb/sdk/wandb_run.py", line 1518, in _console_raw_callback
    self._backend.interface.publish_output_raw(name, data)
  File "/Users/luosmallrui/Library/Python/3.9/lib/python/site-packages/wandb/sdk/interface/interface.py", line 761, in publish_output_raw
    self._publish_output_raw(o)
  File "/Users/luosmallrui/Library/Python/3.9/lib/python/site-packages/wandb/sdk/interface/interface_shared.py", line 38, in _publish_output_raw
    self._publish(rec)
  File "/Users/luosmallrui/Library/Python/3.9/lib/python/site-packages/wandb/sdk/interface/interface_sock.py", line 39, in _publish
    self._sock_client.send_record_publish(record)
  File "/Users/luosmallrui/Library/Python/3.9/lib/python/site-packages/wandb/sdk/lib/sock_client.py", line 174, in send_record_publish
    self.send_server_request(server_req)
  File "/Users/luosmallrui/Library/Python/3.9/lib/python/site-packages/wandb/sdk/lib/sock_client.py", line 154, in send_server_request
    self._send_message(msg)
  File "/Users/luosmallrui/Library/Python/3.9/lib/python/site-packages/wandb/sdk/lib/sock_client.py", line 151, in _send_message
    self._sendall_with_error_handle(header + data)
  File "/Users/luosmallrui/Library/Python/3.9/lib/python/site-packages/wandb/sdk/lib/sock_client.py", line 130, in _sendall_with_error_handle
    sent = self._sock.send(data)
BrokenPipeError: [Errno 32] Broken pipe
2025-07-29 00:16:50,001 ERROR   MainThread:34751 [redirect.py:_on_write():661] [no run ID] error in stderr callback
Traceback (most recent call last):
  File "/Users/luosmallrui/Library/Python/3.9/lib/python/site-packages/wandb/sdk/lib/redirect.py", line 659, in _on_write
    cb(written_data)
  File "/Users/luosmallrui/Library/Python/3.9/lib/python/site-packages/wandb/sdk/wandb_run.py", line 2381, in <lambda>
    lambda data: self._console_raw_callback("stderr", data),
  File "/Users/luosmallrui/Library/Python/3.9/lib/python/site-packages/wandb/sdk/wandb_run.py", line 387, in wrapper
    return func(self, *args, **kwargs)
  File "/Users/luosmallrui/Library/Python/3.9/lib/python/site-packages/wandb/sdk/wandb_run.py", line 435, in wrapper_fn
    return func(self, *args, **kwargs)
  File "/Users/luosmallrui/Library/Python/3.9/lib/python/site-packages/wandb/sdk/wandb_run.py", line 1518, in _console_raw_callback
    self._backend.interface.publish_output_raw(name, data)
  File "/Users/luosmallrui/Library/Python/3.9/lib/python/site-packages/wandb/sdk/interface/interface.py", line 761, in publish_output_raw
    self._publish_output_raw(o)
  File "/Users/luosmallrui/Library/Python/3.9/lib/python/site-packages/wandb/sdk/interface/interface_shared.py", line 38, in _publish_output_raw
    self._publish(rec)
  File "/Users/luosmallrui/Library/Python/3.9/lib/python/site-packages/wandb/sdk/interface/interface_sock.py", line 39, in _publish
    self._sock_client.send_record_publish(record)
  File "/Users/luosmallrui/Library/Python/3.9/lib/python/site-packages/wandb/sdk/lib/sock_client.py", line 174, in send_record_publish
    self.send_server_request(server_req)
  File "/Users/luosmallrui/Library/Python/3.9/lib/python/site-packages/wandb/sdk/lib/sock_client.py", line 154, in send_server_request
    self._send_message(msg)
  File "/Users/luosmallrui/Library/Python/3.9/lib/python/site-packages/wandb/sdk/lib/sock_client.py", line 151, in _send_message
    self._sendall_with_error_handle(header + data)
  File "/Users/luosmallrui/Library/Python/3.9/lib/python/site-packages/wandb/sdk/lib/sock_client.py", line 130, in _sendall_with_error_handle
    sent = self._sock.send(data)
BrokenPipeError: [Errno 32] Broken pipe
2025-07-29 00:16:50,002 ERROR   MainThread:34751 [redirect.py:_on_write():661] [no run ID] error in stderr callback
Traceback (most recent call last):
  File "/Users/luosmallrui/Library/Python/3.9/lib/python/site-packages/wandb/sdk/lib/redirect.py", line 659, in _on_write
    cb(written_data)
  File "/Users/luosmallrui/Library/Python/3.9/lib/python/site-packages/wandb/sdk/wandb_run.py", line 2381, in <lambda>
    lambda data: self._console_raw_callback("stderr", data),
  File "/Users/luosmallrui/Library/Python/3.9/lib/python/site-packages/wandb/sdk/wandb_run.py", line 387, in wrapper
    return func(self, *args, **kwargs)
  File "/Users/luosmallrui/Library/Python/3.9/lib/python/site-packages/wandb/sdk/wandb_run.py", line 435, in wrapper_fn
    return func(self, *args, **kwargs)
  File "/Users/luosmallrui/Library/Python/3.9/lib/python/site-packages/wandb/sdk/wandb_run.py", line 1518, in _console_raw_callback
    self._backend.interface.publish_output_raw(name, data)
  File "/Users/luosmallrui/Library/Python/3.9/lib/python/site-packages/wandb/sdk/interface/interface.py", line 761, in publish_output_raw
    self._publish_output_raw(o)
  File "/Users/luosmallrui/Library/Python/3.9/lib/python/site-packages/wandb/sdk/interface/interface_shared.py", line 38, in _publish_output_raw
    self._publish(rec)
  File "/Users/luosmallrui/Library/Python/3.9/lib/python/site-packages/wandb/sdk/interface/interface_sock.py", line 39, in _publish
    self._sock_client.send_record_publish(record)
  File "/Users/luosmallrui/Library/Python/3.9/lib/python/site-packages/wandb/sdk/lib/sock_client.py", line 174, in send_record_publish
    self.send_server_request(server_req)
  File "/Users/luosmallrui/Library/Python/3.9/lib/python/site-packages/wandb/sdk/lib/sock_client.py", line 154, in send_server_request
    self._send_message(msg)
  File "/Users/luosmallrui/Library/Python/3.9/lib/python/site-packages/wandb/sdk/lib/sock_client.py", line 151, in _send_message
    self._sendall_with_error_handle(header + data)
  File "/Users/luosmallrui/Library/Python/3.9/lib/python/site-packages/wandb/sdk/lib/sock_client.py", line 130, in _sendall_with_error_handle
    sent = self._sock.send(data)
BrokenPipeError: [Errno 32] Broken pipe
2025-07-29 00:16:50,003 ERROR   MainThread:34751 [redirect.py:_on_write():661] [no run ID] error in stderr callback
Traceback (most recent call last):
  File "/Users/luosmallrui/Library/Python/3.9/lib/python/site-packages/wandb/sdk/lib/redirect.py", line 659, in _on_write
    cb(written_data)
  File "/Users/luosmallrui/Library/Python/3.9/lib/python/site-packages/wandb/sdk/wandb_run.py", line 2381, in <lambda>
    lambda data: self._console_raw_callback("stderr", data),
  File "/Users/luosmallrui/Library/Python/3.9/lib/python/site-packages/wandb/sdk/wandb_run.py", line 387, in wrapper
    return func(self, *args, **kwargs)
  File "/Users/luosmallrui/Library/Python/3.9/lib/python/site-packages/wandb/sdk/wandb_run.py", line 435, in wrapper_fn
    return func(self, *args, **kwargs)
  File "/Users/luosmallrui/Library/Python/3.9/lib/python/site-packages/wandb/sdk/wandb_run.py", line 1518, in _console_raw_callback
    self._backend.interface.publish_output_raw(name, data)
  File "/Users/luosmallrui/Library/Python/3.9/lib/python/site-packages/wandb/sdk/interface/interface.py", line 761, in publish_output_raw
    self._publish_output_raw(o)
  File "/Users/luosmallrui/Library/Python/3.9/lib/python/site-packages/wandb/sdk/interface/interface_shared.py", line 38, in _publish_output_raw
    self._publish(rec)
  File "/Users/luosmallrui/Library/Python/3.9/lib/python/site-packages/wandb/sdk/interface/interface_sock.py", line 39, in _publish
    self._sock_client.send_record_publish(record)
  File "/Users/luosmallrui/Library/Python/3.9/lib/python/site-packages/wandb/sdk/lib/sock_client.py", line 174, in send_record_publish
    self.send_server_request(server_req)
  File "/Users/luosmallrui/Library/Python/3.9/lib/python/site-packages/wandb/sdk/lib/sock_client.py", line 154, in send_server_request
    self._send_message(msg)
  File "/Users/luosmallrui/Library/Python/3.9/lib/python/site-packages/wandb/sdk/lib/sock_client.py", line 151, in _send_message
    self._sendall_with_error_handle(header + data)
  File "/Users/luosmallrui/Library/Python/3.9/lib/python/site-packages/wandb/sdk/lib/sock_client.py", line 130, in _sendall_with_error_handle
    sent = self._sock.send(data)
BrokenPipeError: [Errno 32] Broken pipe
2025-07-29 00:16:50,004 ERROR   MainThread:34751 [redirect.py:_on_write():661] [no run ID] error in stderr callback
Traceback (most recent call last):
  File "/Users/luosmallrui/Library/Python/3.9/lib/python/site-packages/wandb/sdk/lib/redirect.py", line 659, in _on_write
    cb(written_data)
  File "/Users/luosmallrui/Library/Python/3.9/lib/python/site-packages/wandb/sdk/wandb_run.py", line 2381, in <lambda>
    lambda data: self._console_raw_callback("stderr", data),
  File "/Users/luosmallrui/Library/Python/3.9/lib/python/site-packages/wandb/sdk/wandb_run.py", line 387, in wrapper
    return func(self, *args, **kwargs)
  File "/Users/luosmallrui/Library/Python/3.9/lib/python/site-packages/wandb/sdk/wandb_run.py", line 435, in wrapper_fn
    return func(self, *args, **kwargs)
  File "/Users/luosmallrui/Library/Python/3.9/lib/python/site-packages/wandb/sdk/wandb_run.py", line 1518, in _console_raw_callback
    self._backend.interface.publish_output_raw(name, data)
  File "/Users/luosmallrui/Library/Python/3.9/lib/python/site-packages/wandb/sdk/interface/interface.py", line 761, in publish_output_raw
    self._publish_output_raw(o)
  File "/Users/luosmallrui/Library/Python/3.9/lib/python/site-packages/wandb/sdk/interface/interface_shared.py", line 38, in _publish_output_raw
    self._publish(rec)
  File "/Users/luosmallrui/Library/Python/3.9/lib/python/site-packages/wandb/sdk/interface/interface_sock.py", line 39, in _publish
    self._sock_client.send_record_publish(record)
  File "/Users/luosmallrui/Library/Python/3.9/lib/python/site-packages/wandb/sdk/lib/sock_client.py", line 174, in send_record_publish
    self.send_server_request(server_req)
  File "/Users/luosmallrui/Library/Python/3.9/lib/python/site-packages/wandb/sdk/lib/sock_client.py", line 154, in send_server_request
    self._send_message(msg)
  File "/Users/luosmallrui/Library/Python/3.9/lib/python/site-packages/wandb/sdk/lib/sock_client.py", line 151, in _send_message
    self._sendall_with_error_handle(header + data)
  File "/Users/luosmallrui/Library/Python/3.9/lib/python/site-packages/wandb/sdk/lib/sock_client.py", line 130, in _sendall_with_error_handle
    sent = self._sock.send(data)
BrokenPipeError: [Errno 32] Broken pipe
2025-07-29 00:16:50,004 ERROR   MainThread:34751 [redirect.py:_on_write():661] [no run ID] error in stderr callback
Traceback (most recent call last):
  File "/Users/luosmallrui/Library/Python/3.9/lib/python/site-packages/wandb/sdk/lib/redirect.py", line 659, in _on_write
    cb(written_data)
  File "/Users/luosmallrui/Library/Python/3.9/lib/python/site-packages/wandb/sdk/wandb_run.py", line 2381, in <lambda>
    lambda data: self._console_raw_callback("stderr", data),
  File "/Users/luosmallrui/Library/Python/3.9/lib/python/site-packages/wandb/sdk/wandb_run.py", line 387, in wrapper
    return func(self, *args, **kwargs)
  File "/Users/luosmallrui/Library/Python/3.9/lib/python/site-packages/wandb/sdk/wandb_run.py", line 435, in wrapper_fn
    return func(self, *args, **kwargs)
  File "/Users/luosmallrui/Library/Python/3.9/lib/python/site-packages/wandb/sdk/wandb_run.py", line 1518, in _console_raw_callback
    self._backend.interface.publish_output_raw(name, data)
  File "/Users/luosmallrui/Library/Python/3.9/lib/python/site-packages/wandb/sdk/interface/interface.py", line 761, in publish_output_raw
    self._publish_output_raw(o)
  File "/Users/luosmallrui/Library/Python/3.9/lib/python/site-packages/wandb/sdk/interface/interface_shared.py", line 38, in _publish_output_raw
    self._publish(rec)
  File "/Users/luosmallrui/Library/Python/3.9/lib/python/site-packages/wandb/sdk/interface/interface_sock.py", line 39, in _publish
    self._sock_client.send_record_publish(record)
  File "/Users/luosmallrui/Library/Python/3.9/lib/python/site-packages/wandb/sdk/lib/sock_client.py", line 174, in send_record_publish
    self.send_server_request(server_req)
  File "/Users/luosmallrui/Library/Python/3.9/lib/python/site-packages/wandb/sdk/lib/sock_client.py", line 154, in send_server_request
    self._send_message(msg)
  File "/Users/luosmallrui/Library/Python/3.9/lib/python/site-packages/wandb/sdk/lib/sock_client.py", line 151, in _send_message
    self._sendall_with_error_handle(header + data)
  File "/Users/luosmallrui/Library/Python/3.9/lib/python/site-packages/wandb/sdk/lib/sock_client.py", line 130, in _sendall_with_error_handle
    sent = self._sock.send(data)
BrokenPipeError: [Errno 32] Broken pipe
2025-07-29 00:16:50,004 ERROR   MainThread:34751 [redirect.py:_on_write():661] [no run ID] error in stderr callback
Traceback (most recent call last):
  File "/Users/luosmallrui/Library/Python/3.9/lib/python/site-packages/wandb/sdk/lib/redirect.py", line 659, in _on_write
    cb(written_data)
  File "/Users/luosmallrui/Library/Python/3.9/lib/python/site-packages/wandb/sdk/wandb_run.py", line 2381, in <lambda>
    lambda data: self._console_raw_callback("stderr", data),
  File "/Users/luosmallrui/Library/Python/3.9/lib/python/site-packages/wandb/sdk/wandb_run.py", line 387, in wrapper
    return func(self, *args, **kwargs)
  File "/Users/luosmallrui/Library/Python/3.9/lib/python/site-packages/wandb/sdk/wandb_run.py", line 435, in wrapper_fn
    return func(self, *args, **kwargs)
  File "/Users/luosmallrui/Library/Python/3.9/lib/python/site-packages/wandb/sdk/wandb_run.py", line 1518, in _console_raw_callback
    self._backend.interface.publish_output_raw(name, data)
  File "/Users/luosmallrui/Library/Python/3.9/lib/python/site-packages/wandb/sdk/interface/interface.py", line 761, in publish_output_raw
    self._publish_output_raw(o)
  File "/Users/luosmallrui/Library/Python/3.9/lib/python/site-packages/wandb/sdk/interface/interface_shared.py", line 38, in _publish_output_raw
    self._publish(rec)
  File "/Users/luosmallrui/Library/Python/3.9/lib/python/site-packages/wandb/sdk/interface/interface_sock.py", line 39, in _publish
    self._sock_client.send_record_publish(record)
  File "/Users/luosmallrui/Library/Python/3.9/lib/python/site-packages/wandb/sdk/lib/sock_client.py", line 174, in send_record_publish
    self.send_server_request(server_req)
  File "/Users/luosmallrui/Library/Python/3.9/lib/python/site-packages/wandb/sdk/lib/sock_client.py", line 154, in send_server_request
    self._send_message(msg)
  File "/Users/luosmallrui/Library/Python/3.9/lib/python/site-packages/wandb/sdk/lib/sock_client.py", line 151, in _send_message
    self._sendall_with_error_handle(header + data)
  File "/Users/luosmallrui/Library/Python/3.9/lib/python/site-packages/wandb/sdk/lib/sock_client.py", line 130, in _sendall_with_error_handle
    sent = self._sock.send(data)
BrokenPipeError: [Errno 32] Broken pipe
2025-07-29 00:16:50,005 ERROR   MainThread:34751 [redirect.py:_on_write():661] [no run ID] error in stderr callback
Traceback (most recent call last):
  File "/Users/luosmallrui/Library/Python/3.9/lib/python/site-packages/wandb/sdk/lib/redirect.py", line 659, in _on_write
    cb(written_data)
  File "/Users/luosmallrui/Library/Python/3.9/lib/python/site-packages/wandb/sdk/wandb_run.py", line 2381, in <lambda>
    lambda data: self._console_raw_callback("stderr", data),
  File "/Users/luosmallrui/Library/Python/3.9/lib/python/site-packages/wandb/sdk/wandb_run.py", line 387, in wrapper
    return func(self, *args, **kwargs)
  File "/Users/luosmallrui/Library/Python/3.9/lib/python/site-packages/wandb/sdk/wandb_run.py", line 435, in wrapper_fn
    return func(self, *args, **kwargs)
  File "/Users/luosmallrui/Library/Python/3.9/lib/python/site-packages/wandb/sdk/wandb_run.py", line 1518, in _console_raw_callback
    self._backend.interface.publish_output_raw(name, data)
  File "/Users/luosmallrui/Library/Python/3.9/lib/python/site-packages/wandb/sdk/interface/interface.py", line 761, in publish_output_raw
    self._publish_output_raw(o)
  File "/Users/luosmallrui/Library/Python/3.9/lib/python/site-packages/wandb/sdk/interface/interface_shared.py", line 38, in _publish_output_raw
    self._publish(rec)
  File "/Users/luosmallrui/Library/Python/3.9/lib/python/site-packages/wandb/sdk/interface/interface_sock.py", line 39, in _publish
    self._sock_client.send_record_publish(record)
  File "/Users/luosmallrui/Library/Python/3.9/lib/python/site-packages/wandb/sdk/lib/sock_client.py", line 174, in send_record_publish
    self.send_server_request(server_req)
  File "/Users/luosmallrui/Library/Python/3.9/lib/python/site-packages/wandb/sdk/lib/sock_client.py", line 154, in send_server_request
    self._send_message(msg)
  File "/Users/luosmallrui/Library/Python/3.9/lib/python/site-packages/wandb/sdk/lib/sock_client.py", line 151, in _send_message
    self._sendall_with_error_handle(header + data)
  File "/Users/luosmallrui/Library/Python/3.9/lib/python/site-packages/wandb/sdk/lib/sock_client.py", line 130, in _sendall_with_error_handle
    sent = self._sock.send(data)
BrokenPipeError: [Errno 32] Broken pipe
